### Exception Handling ###

numberOne = 5
numberTwo = 1
numberTwo = "1"

# ExcepciÃ³n base: try except

try:
    print(numberOne + numberTwo)
    print("No se ha producido un error")
except:
    # Se ejecuta si se produce una excepciÃ³n
    print("Se ha producido un error")

# Flujo completo de una excepciÃ³n: try except else finally

try:
    print(numberOne + numberTwo)
    print("No se ha producido un error")
except:
    print("Se ha producido un error")
else:  # Opcional
    # Se ejecuta si no se produce una excepciÃ³n
    print("La ejecuciÃ³n continÃºa correctamente")
finally:  # Opcional
    # Se ejecuta siempre
    print("La ejecuciÃ³n continÃºa")

# Excepciones por tipo

try:
    print(numberOne + numberTwo)
    print("No se ha producido un error")
except ValueError:
    print("Se ha producido un ValueError")
except TypeError:
    print("Se ha producido un TypeError")

# Captura de la informaciÃ³n de la excepciÃ³n

try:
    print(numberOne + numberTwo)
    print("No se ha producido un error")
except ValueError as error:
    print(error)
except Exception as my_random_error_name:
    print(my_random_error_name)